Workbook

Sheet TOTALES FINALES
C2: TOTALES GENERALES
C5: TOTAL PERSONAS | D5: =+D37+D52+D67+D82+D97+D112+D127+D142 -> 3690 | F5: TOTALES CENTROS | G5: =+G37+G52+G67+G82+G97+G112+G127+G142 -> 49
C6: NRO. FAMILIAS | D6: =+D38+D53+D68+D83+D98+D113+D128+D143 -> 1382 | F6: OPERATIVOS | G6: =+G38+G53+G68+G83+G98+G113+G128+G143 -> 18
C7: HOMBRES | D7: =+D39+D54+D69+D84+D99+D114+D129+D144 -> 677 | F7: EN ESPERA DE PERSONAS | G7: =+G39+G54+G69+G84+G99+G114+G129+G144 -> 31
C8: MUJERES | D8: =+D40+D55+D70+D85+D100+D115+D130+D145 -> 877
C9: NIÑOS | D9: =+D41+D56+D71+D86+D101+D116+D131+D146 -> 524 | F9: =D7+D8+D9+D10+D11+D12 -> 2876 | G9: CENSADOS
C10: NIÑAS | D10: =+D42+D57+D72+D87+D102+D117+D132+D147 -> 554
C11: ADULTOS MAYORES | D11: =+D43+D58+D73+D88+D103+D118+D133+D148 -> 143 | F11: =D5-F9 -> 814 | G11: POR CENSAR
C12: ADULTAS MAYORES | D12: =+D44+D59+D74+D89+D104+D119+D134+D149 -> 101
C13: PER. CON DISCAPACIDAD | D13: =+D45+D60+D75+D90+D105+D120+D135+D150 -> 2
C14: EMBARAZADAS | D14: =+D46+D61+D76+D91+D106+D121+D136+D151 -> 2
C15: CASOS DE SALUD | D15: =+D47+D62+D77+D92+D107+D122+D137+D152 -> 0
C16: MASCOTAS | D16: =+D48+D63+D78+D93+D108+D123+D138+D153 -> 0
C24: TOTAL PERSONAS | D24: =D25+D26+D27+D28+D29+D30+D31 -> 3690
C25: HOMBRES | D25: 677
C26: MUJERES | D26: 877
C27: NIÑOS | D27: 524
C28: NIÑAS | D28: 554
C29: ADULTOS MAYORES | D29: 143
C30: ADULTAS MAYORES | D30: 101
C31: PERSONAS POR CENSAR | D31: 814
C36: MARIANA
C37: TOTAL PERSONAS | D37: 486 | F37: TOTALES CENTROS | G37: =+G38 -> 5
C38: NRO. FAMILIAS | D38: 161 | F38: OPERATIVOS | G38: =3+2 -> 5
C39: HOMBRES | D39: 42 | F39: EN ESPERA DE PERSONAS | G39: =+'CM YOHANA CARDOZO'!AJ37+'CM FEREICO GUZMAN'!AJ37+'CM CARLOS GAMBOA'!AJ37 -> 0
C40: MUJERES | D40: 56
C41: NIÑOS | D41: 40
C42: NIÑAS | D42: 38 | F42: =100+195 -> 295
C43: ADULTOS MAYORES | D43: 5 | F43: POR CENSAR
C44: ADULTAS MAYORES | D44: 10
C45: PER. CON DISCAPACIDAD | D45: 0
C46: EMBARAZADAS | D46: 0
C47: CASOS DE SALUD | D47: 0
C48: MASCOTAS | D48: 0
C51: SOLER
C52: TOTAL PERSONAS | D52: 483 | F52: TOTALES CENTROS | G52: 8 | H52: 10
C53: NRO. FAMILIAS | D53: 104 | F53: OPERATIVOS | G53: 2
C54: HOMBRES | D54: 124 | F54: EN ESPERA DE PERSONAS | G54: 6
C55: MUJERES | D55: 121
C56: NIÑOS | D56: 54
...

Sheet CM FEREICO GUZMAN
AI2: TOTALES
C3: CENTRO: ETI LEONARDO INFANTE | I3: CENTRO: UEN MARIANO PICON SALAS | O3: CENTRO: XXXXXXXX XXXXXXXXXX XXXXXXXX | U3: CENTRO: XXXXXXXX XXXXXXXXXX XXXXXXXX | AA3: CENTRO: XXXXXXXX XXXXXXXXXX XXXXXXXX
B4: PRESENTACION | C4: TOTAL PERSONAS | D4: =D6+D7+D8+D9+D10+D11 -> 12 | H4: PRESENTACION | I4: TOTAL PERSONAS | J4: 195 | N4: PRESENTACION | O4: TOTAL PERSONAS | P4: =P6+P7+P8+P9+P10+P11 -> 0 | T4: PRESENTACION | U4: TOTAL PERSONAS | V4: =V6+V7+V8+V9+V10+V11 -> 0 | Z4: PRESENTACION | AA4: TOTAL PERSONAS | AB4: =AB6+AB7+AB8+AB9+AB10+AB11 -> 0 | AI4: TOTAL PERSONAS | AJ4: =J4+P4+V4+D4 -> 207
C5: NRO. FAMILIAS | D5: 1 | I5: NRO. FAMILIAS | J5: 60 | O5: NRO. FAMILIAS | P5: 0 | U5: NRO. FAMILIAS | V5: 0 | AA5: NRO. FAMILIAS | AB5: 0 | AI5: NRO. FAMILIAS | AJ5: =J5+P5+V5+D5 -> 61
C6: HOMBRES | D6: 3 | I6: HOMBRES | J6: 0 | O6: HOMBRES | P6: 0 | U6: HOMBRES | V6: 0 | AA6: HOMBRES | AB6: 0 | AI6: HOMBRES | AJ6: =+J6+P6+V6+D6 -> 3
C7: MUJERES | D7: 4 | I7: MUJERES | J7: 0 | O7: MUJERES | P7: 0 | U7: MUJERES | V7: 0 | AA7: MUJERES | AB7: 0 | AI7: MUJERES | AJ7: =+J7+P7+V7+D7 -> 4
C8: NIÑOS | D8: 2 | I8: NIÑOS | J8: 0 | O8: NIÑOS | P8: 0 | U8: NIÑOS | V8: 0 | AA8: NIÑOS | AB8: 0 | AI8: NIÑOS | AJ8: =+J8+P8+V8+D8 -> 2
C9: NIÑAS | D9: 2 | I9: NIÑAS | J9: 0 | O9: NIÑAS | P9: 0 | U9: NIÑAS | V9: 0 | AA9: NIÑAS | AB9: 0 | AI9: NIÑAS | AJ9: =+J9+P9+V9+D9 -> 2
C10: ADULTOS MAYORES | D10: 0 | I10: ADULTOS MAYORES | J10: 0 | O10: ADULTOS MAYORES | P10: 0 | U10: ADULTOS MAYORES | V10: 0 | AA10: ADULTOS MAYORES | AB10: 0 | AI10: ADULTOS MAYORES | AJ10: =+J10+P10+V10+D10 -> 0
C11: ADULTAS MAYORES | D11: 1 | E11: FOTO DEL CENTRO | I11: ADULTAS MAYORES | J11: 0 | K11: FOTO DEL CENTRO | O11: ADULTAS MAYORES | P11: 0 | Q11: FOTO DEL CENTRO | U11: ADULTAS MAYORES | V11: 0 | W11: FOTO DEL CENTRO | AA11: ADULTAS MAYORES | AB11: 0 | AC11: FOTO DEL CENTRO | AI11: ADULTAS MAYORES | AJ11: =+J11+P11+V11+D11 -> 1
C12: PER. CON DISCAPACIDAD | D12: 0 | I12: PER. CON DISCAPACIDAD | J12: 0 | O12: PER. CON DISCAPACIDAD | P12: 0 | U12: PER. CON DISCAPACIDAD | V12: 0 | AA12: PER. CON DISCAPACIDAD | AB12: 0 | AI12: PER. CON DISCAPACIDAD | AJ12: =+J12+P12+V12+D12 -> 0
C13: EMBARAZADAS | D13: 0 | I13: EMBARAZADAS | J13: 0 | O13: EMBARAZADAS | P13: 0 | U13: EMBARAZADAS | V13: 0 | AA13: EMBARAZADAS | AB13: 0 | AI13: EMBARAZADAS | AJ13: =+J13+P13+V13+D13 -> 0
C14: CASOS DE SALUD | D14: 0 | I14: CASOS DE SALUD | J14: 0 | O14: CASOS DE SALUD | P14: 0 | U14: CASOS DE SALUD | V14: 0 | AA14: CASOS DE SALUD | AB14: 0 | AI14: CASOS DE SALUD | AJ14: =+J14+P14+V14+D14 -> 0
C15: MASCOTAS | D15: 0 | I15: MASCOTAS | J15: 0 | O15: MASCOTAS | P15: 0 | U15: MASCOTAS | V15: 0 | AA15: MASCOTAS | AB15: 0 | AI15: MASCOTAS | AJ15: =+J15+P15+V15+D15 -> 0
B17: I | C17: ESTADO | D17: MIRANDA | H17: I | I17: ESTADO | J17: DTTO. CAPITAL | N17: I | O17: ESTADO | P17: DTTO. CAPITAL | T17: I | U17: ESTADO | V17: DTTO. CAPITAL | Z17: I | AA17: ESTADO | AB17: DTTO. CAPITAL
C18: MUNICIPIO | D18: SUCRE | I18: MUNICIPIO | J18: SUCRE | O18: MUNICIPIO | P18: LIBERTADOR | U18: MUNICIPIO | V18: LIBERTADOR | AA18: MUNICIPIO | AB18: LIBERTADOR
C19: PARROQUIA | D19: PETARE | I19: PARROQUIA | J19: MIRANDA | O19: PARROQUIA | P19: XXXX | U19: PARROQUIA | V19: XXXX | AA19: PARROQUIA | AB19: XXXX | AI19: TOTALES CENTROS | AJ19: =+AJ20+AJ21 -> 2
C20: COORDENADAS | I20: COORDENADAS | O20: COORDENADAS | P20: XXXX | U20: COORDENADAS | V20: XXXX | AA20: COORDENADAS | AB20: XXXX | AI20: OPERATIVOS | AJ20: 2
B21: II | C21: COORDINADOR POLÍTICO | D21: JOSE PERDOMO | H21: II | I21: COORDINADOR POLÍTICO | J21: JHONATAHAN SAYAGO | N21: II | O21: COORDINADOR POLÍTICO | P21: XXXXX XXXXXX | T21: II | U21: COORDINADOR POLÍTICO | V21: XXXXX XXXXXX | Z21: II | AA21: COORDINADOR POLÍTICO | AB21: XXXXX XXXXXX | AI21: EN ESPERA DE PERSONAS
C22: CEDULA | D22: 6506555 | I22: CEDULA | J22: 19650607 | O22: CEDULA | P22: XX.XXX.XXX | U22: CEDULA | V22: XX.XXX.XXX | AA22: CEDULA | AB22: XX.XXX.XXX
C23: TÉLEFONO | D23: 0412-9851839 | I23: TÉLEFONO | J23: 0414-2310314 | O23: TÉLEFONO | P23: XXXX-XXXXXXX | U23: TÉLEFONO | V23: XXXX-XXXXXXX | AA23: TÉLEFONO | AB23: XXXX-XXXXXXX
C24: ENTE A CARGO | D24: MINISTERIO DE DESARROLLO MINERO E INDUSTRIAS BASICAS | I24: ENTE A CARGO | J24: ALCALDIA MUNICIPIO SUCRE | O24: ENTE A CARGO | P24: XXXXXXXX | U24: ENTE A CARGO | V24: XXXXXXXX | AA24: ENTE A CARGO | AB24: XXXXXXXX
B25: III | C25: JEFE DE SEGURIDAD | D25: C/G JESUS VILORIA | H25: III | I25: JEFE DE SEGURIDAD | J25: P/C HENRY NAVEDA | N25: III | O25: JEFE DE SEGURIDAD | P25: XXXXXXX XXXXX | T25: III | U25: JEFE DE SEGURIDAD | V25: XXXXXXX XXXXX | Z25: III | AA25: JEFE DE SEGURIDAD | AB25: XXXXXXX XXXXX
C26: CEDULA | D26: 15584882 | I26: CEDULA | J26: 9413629 | O26: CEDULA | P26: XX.XXX.XXX | U26: CEDULA | V26: XX.XXX.XXX | AA26: CEDULA | AB26: XX.XXX.XXX
C27: TÉLEFONO | D27: 0426-520-8455 | I27: TÉLEFONO | J27: 0412-4693297 | O27: TÉLEFONO | P27: XXXX-XXXXXXX | U27: TÉLEFONO | V27: XXXX-XXXXXXX | AA27: TÉLEFONO | AB27: XXXX-XXXXXXX
C28: ORGANISMO DE SEGURIDAD | D28: SEBIN | I28: ORGANISMO DE SEGURIDAD | J28: SEBIN | O28: ORGANISMO DE SEGURIDAD | P28: XXXXXX | U28: ORGANISMO DE SEGURIDAD | V28: XXXXXX | AA28: ORGANISMO DE SEGURIDAD | AB28: XXXXXX
C29: PERSONAL A SU MANDO | D29: 17 FUNCIONARIOS/14 MASCULINOS/3 FEMENINAS | I29: PERSONAL A SU MANDO | J29: 15 | O29: PERSONAL A SU MANDO | P29: XX | U29: PERSONAL A SU MANDO | V29: XX | AA29: PERSONAL A SU MANDO | AB29: XX
C30: VEHICULOS | D30: 1 TOYOTA 4RUNNER | I30: VEHICULOS | J30: 5 | O30: VEHICULOS | P30: XX | U30: VEHICULOS | V30: XX | AA30: VEHICULOS | AB30: XX
B31: IV | C31: MEDICOS EN EL CENTRO | D31: SI | H31: IV | I31: MEDICOS EN EL CENTRO | J31: SI | N31: IV | O31: MEDICOS EN EL CENTRO | P31: SI/NO | T31: IV | U31: MEDICOS EN EL CENTRO | V31: SI/NO | Z31: IV | AA31: MEDICOS EN EL CENTRO | AB31: SI/NO
C32: AMBULANCIAS | D32: SI | I32: AMBULANCIAS | J32: SI | O32: AMBULANCIAS | P32: SI/NO | U32: AMBULANCIAS | V32: SI/NO | AA32: AMBULANCIAS | AB32: SI/NO
C33: PSICOLOGO | D33: SI | I33: PSICOLOGO | J33: SI | O33: PSICOLOGO | P33: SI/NO | U33: PSICOLOGO | V33: SI/NO | AA33: PSICOLOGO | AB33: SI/NO
C34: CONTACTO JUEZ DE PAZ | D34: NO | I34: CONTACTO JUEZ DE PAZ | J34: SI | O34: CONTACTO JUEZ DE PAZ | P34: SI/NO | U34: CONTACTO JUEZ DE PAZ | V34: SI/NO | AA34: CONTACTO JUEZ DE PAZ | AB34: SI/NO
B35: VI | C35: NOVEDADES RELEVANTES | H35: VI | I35: NOVEDADES RELEVANTES | N35: VI | O35: NOVEDADES RELEVANTES | T35: VI | U35: NOVEDADES RELEVANTES | Z35: VI | AA35: NOVEDADES RELEVANTES
C36: SE ESTIMA QUE PARA EL DIA DE HOY COMIENCE A LLEGAR LOS DEMAS GRUPOS DE DAMNIFICADOS | I36: LA UNIDAD EDUCATIVA SE ENCUENTRA EN PROCESO DE CENSO Y RECOLECCION DE INFORMACION | O36: Describir novedad | U36: Describir novedad | AA36: Describir novedad
C37: Describir novedad | I37: Describir novedad | O37: Describir novedad | U37: Describir novedad | AA37: Describir novedad
C38: Describir novedad | I38: Describir novedad | O38: Describir novedad | U38: Describir novedad | AA38: Describir novedad
C39: Describir novedad | I39: Describir novedad | O39: Describir novedad | U39: Describir novedad | AA39: Describir novedad
C41: ANALISTA SAE | D41: COMISARIO MARIANA LANDAETA | I41: ANALISTA SAE | J41: COMISARIO MARIANA LANDAETA | O41: ANALISTA SAE | P41: PROF. XXXX | U41: ANALISTA SAE | V41: PROF. XXXX | AA41: ANALISTA SAE | AB41: PROF. XXXX
C42: SUPERVISOR SEBIN | D42: C/G GUZMAN | I42: SUPERVISOR SEBIN | J42: C/G GUZMAN | O42: SUPERVISOR SEBIN | P42: C/G XXXXX | U42: SUPERVISOR SEBIN | V42: C/G XXXXX | AA42: SUPERVISOR SEBIN | AB42: C/G XXXXX

Sheet CM CARLOS GAMBOA
AI2: TOTALES
C3: CENTRO: ESCUELA NACIONAL DE ARTES ESCÉNICAS CESAR RENGIFO | I3: CENTRO: XXXXXXXX XXXXXXXXXX XXXXXXXX | O3: CENTRO: XXXXXXXX XXXXXXXXXX XXXXXXXX | U3: CENTRO: XXXXXXXX XXXXXXXXXX XXXXXXXX | AA3: CENTRO: XXXXXXXX XXXXXXXXXX XXXXXXXX
B4: PRESENTACION | C4: TOTAL PERSONAS | D4: =D6+D7+D8+D9+D10+D11 -> 16 | H4: PRESENTACION | I4: TOTAL PERSONAS | J4: =J6+J7+J8+J9+J10+J11 -> 0 | N4: PRESENTACION | O4: TOTAL PERSONAS | P4: =P6+P7+P8+P9+P10+P11 -> 0 | T4: PRESENTACION | U4: TOTAL PERSONAS | V4: =V6+V7+V8+V9+V10+V11 -> 0 | Z4: PRESENTACION | AA4: TOTAL PERSONAS | AB4: =AB6+AB7+AB8+AB9+AB10+AB11 -> 0 | AI4: TOTAL PERSONAS | AJ4: =J4+P4+V4 -> 0
C5: NRO. FAMILIAS | D5: 6 | I5: NRO. FAMILIAS | J5: 0 | O5: NRO. FAMILIAS | P5: 0 | U5: NRO. FAMILIAS | V5: 0 | AA5: NRO. FAMILIAS | AB5: 0 | AI5: NRO. FAMILIAS | AJ5: =J5+P5+V5 -> 0
C6: HOMBRES | D6: 2 | I6: HOMBRES | J6: 0 | O6: HOMBRES | P6: 0 | U6: HOMBRES | V6: 0 | AA6: HOMBRES | AB6: 0 | AI6: HOMBRES | AJ6: =+J6+P6+V6 -> 0
C7: MUJERES | D7: 4 | I7: MUJERES | J7: 0 | O7: MUJERES | P7: 0 | U7: MUJERES | V7: 0 | AA7: MUJERES | AB7: 0 | AI7: MUJERES | AJ7: =+J7+P7+V7 -> 0
C8: NIÑOS | D8: 2 | I8: NIÑOS | J8: 0 | O8: NIÑOS | P8: 0 | U8: NIÑOS | V8: 0 | AA8: NIÑOS | AB8: 0 | AI8: NIÑOS | AJ8: =+J8+P8+V8 -> 0
C9: NIÑAS | D9: 3 | I9: NIÑAS | J9: 0 | O9: NIÑAS | P9: 0 | U9: NIÑAS | V9: 0 | AA9: NIÑAS | AB9: 0 | AI9: NIÑAS | AJ9: =+J9+P9+V9 -> 0
C10: ADULTOS MAYORES | D10: 3 | I10: ADULTOS MAYORES | J10: 0 | O10: ADULTOS MAYORES | P10: 0 | U10: ADULTOS MAYORES | V10: 0 | AA10: ADULTOS MAYORES | AB10: 0 | AI10: ADULTOS MAYORES | AJ10: =+J10+P10+V10 -> 0
C11: ADULTAS MAYORES | D11: 2 | E11: FOTO DEL CENTRO | I11: ADULTAS MAYORES | J11: 0 | K11: FOTO DEL CENTRO | O11: ADULTAS MAYORES | P11: 0 | Q11: FOTO DEL CENTRO | U11: ADULTAS MAYORES | V11: 0 | W11: FOTO DEL CENTRO | AA11: ADULTAS MAYORES | AB11: 0 | AC11: FOTO DEL CENTRO | AI11: ADULTAS MAYORES | AJ11: =+J11+P11+V11 -> 0
C12: PER. CON DISCAPACIDAD | D12: 0 | I12: PER. CON DISCAPACIDAD | J12: 0 | O12: PER. CON DISCAPACIDAD | P12: 0 | U12: PER. CON DISCAPACIDAD | V12: 0 | AA12: PER. CON DISCAPACIDAD | AB12: 0 | AI12: PER. CON DISCAPACIDAD | AJ12: =+J12+P12+V12 -> 0
C13: EMBARAZADAS | D13: 0 | I13: EMBARAZADAS | J13: 0 | O13: EMBARAZADAS | P13: 0 | U13: EMBARAZADAS | V13: 0 | AA13: EMBARAZADAS | AB13: 0 | AI13: EMBARAZADAS | AJ13: =+J13+P13+V13 -> 0
C14: CASOS DE SALUD | D14: 0 | I14: CASOS DE SALUD | J14: 0 | O14: CASOS DE SALUD | P14: 0 | U14: CASOS DE SALUD | V14: 0 | AA14: CASOS DE SALUD | AB14: 0 | AI14: CASOS DE SALUD | AJ14: =+J14+P14+V14 -> 0
C15: MASCOTAS | D15: 0 | I15: MASCOTAS | J15: 0 | O15: MASCOTAS | P15: 0 | U15: MASCOTAS | V15: 0 | AA15: MASCOTAS | AB15: 0 | AI15: MASCOTAS | AJ15: =+J15+P15+V15 -> 0
B17: I | C17: ESTADO | D17: DTTO. CAPITAL | H17: I | I17: ESTADO | J17: DTTO. CAPITAL | N17: I | O17: ESTADO | P17: DTTO. CAPITAL | T17: I | U17: ESTADO | V17: DTTO. CAPITAL | Z17: I | AA17: ESTADO | AB17: DTTO. CAPITAL
C18: MUNICIPIO | D18: LIBERTADOR | I18: MUNICIPIO | J18: LIBERTADOR | O18: MUNICIPIO | P18: LIBERTADOR | U18: MUNICIPIO | V18: LIBERTADOR | AA18: MUNICIPIO | AB18: LIBERTADOR
C19: PARROQUIA | D19: ALTAGRACIAS | I19: PARROQUIA | J19: XXXX | O19: PARROQUIA | P19: XXXX | U19: PARROQUIA | V19: XXXX | AA19: PARROQUIA | AB19: XXXX | AI19: TOTALES CENTROS | AJ19: =+AJ20+AJ21 -> 0
C20: COORDENADAS | D20: 10°30'43.9"N 60°54'54.6W | I20: COORDENADAS | J20: XXXX | O20: COORDENADAS | P20: XXXX | U20: COORDENADAS | V20: XXXX | AA20: COORDENADAS | AB20: XXXX | AI20: OPERATIVOS
B21: II | C21: COORDINADOR POLÍTICO | D21: MIGUEL FIGUEROA | H21: II | I21: COORDINADOR POLÍTICO | J21: XXXXX XXXXXX | N21: II | O21: COORDINADOR POLÍTICO | P21: XXXXX XXXXXX | T21: II | U21: COORDINADOR POLÍTICO | V21: XXXXX XXXXXX | Z21: II | AA21: COORDINADOR POLÍTICO | AB21: XXXXX XXXXXX | AI21: EN ESPERA DE PERSONAS
C22: CEDULA | D22: 11405763 | I22: CEDULA | J22: XX.XXX.XXX | O22: CEDULA | P22: XX.XXX.XXX | U22: CEDULA | V22: XX.XXX.XXX | AA22: CEDULA | AB22: XX.XXX.XXX
C23: TÉLEFONO | D23: 4122944519 | I23: TÉLEFONO | J23: XXXX-XXXXXXX | O23: TÉLEFONO | P23: XXXX-XXXXXXX | U23: TÉLEFONO | V23: XXXX-XXXXXXX | AA23: TÉLEFONO | AB23: XXXX-XXXXXXX
C24: ENTE A CARGO | D24: VICEMINISTRO DE CULTURA AUDIOVISUAL | I24: ENTE A CARGO | J24: XXXXXXXX | O24: ENTE A CARGO | P24: XXXXXXXX | U24: ENTE A CARGO | V24: XXXXXXXX | AA24: ENTE A CARGO | AB24: XXXXXXXX
B25: III | C25: JEFE DE SEGURIDAD | D25: SAUL BRISEÑO | H25: III | I25: JEFE DE SEGURIDAD | J25: XXXXXXX XXXXX | N25: III | O25: JEFE DE SEGURIDAD | P25: XXXXXXX XXXXX | T25: III | U25: JEFE DE SEGURIDAD | V25: XXXXXXX XXXXX | Z25: III | AA25: JEFE DE SEGURIDAD | AB25: XXXXXXX XXXXX
C26: CEDULA | D26: 11994338 | I26: CEDULA | J26: XX.XXX.XXX | O26: CEDULA | P26: XX.XXX.XXX | U26: CEDULA | V26: XX.XXX.XXX | AA26: CEDULA | AB26: XX.XXX.XXX
C27: TÉLEFONO | D27: 4142513102 | I27: TÉLEFONO | J27: XXXX-XXXXXXX | O27: TÉLEFONO | P27: XXXX-XXXXXXX | U27: TÉLEFONO | V27: XXXX-XXXXXXX | AA27: TÉLEFONO | AB27: XXXX-XXXXXXX
C28: ORGANISMO DE SEGURIDAD | D28: SEBIN | I28: ORGANISMO DE SEGURIDAD | J28: XXXXXX | O28: ORGANISMO DE SEGURIDAD | P28: XXXXXX | U28: ORGANISMO DE SEGURIDAD | V28: XXXXXX | AA28: ORGANISMO DE SEGURIDAD | AB28: XXXXXX
C29: PERSONAL A SU MANDO | D29: 9 | I29: PERSONAL A SU MANDO | J29: XX | O29: PERSONAL A SU MANDO | P29: XX | U29: PERSONAL A SU MANDO | V29: XX | AA29: PERSONAL A SU MANDO | AB29: XX
C30: VEHICULOS | D30: 1 | I30: VEHICULOS | J30: XX | O30: VEHICULOS | P30: XX | U30: VEHICULOS | V30: XX | AA30: VEHICULOS | AB30: XX
B31: IV | C31: MEDICOS EN EL CENTRO | D31: NO | H31: IV | I31: MEDICOS EN EL CENTRO | J31: SI/NO | N31: IV | O31: MEDICOS EN EL CENTRO | P31: SI/NO | T31: IV | U31: MEDICOS EN EL CENTRO | V31: SI/NO | Z31: IV | AA31: MEDICOS EN EL CENTRO | AB31: SI/NO
C32: AMBULANCIAS | D32: NO | I32: AMBULANCIAS | J32: SI/NO | O32: AMBULANCIAS | P32: SI/NO | U32: AMBULANCIAS | V32: SI/NO | AA32: AMBULANCIAS | AB32: SI/NO
C33: PSICOLOGO | D33: NO | I33: PSICOLOGO | J33: SI/NO | O33: PSICOLOGO | P33: SI/NO | U33: PSICOLOGO | V33: SI/NO | AA33: PSICOLOGO | AB33: SI/NO
C34: CONTACTO JUEZ DE PAZ | D34: SI | I34: CONTACTO JUEZ DE PAZ | J34: SI/NO | O34: CONTACTO JUEZ DE PAZ | P34: SI/NO | U34: CONTACTO JUEZ DE PAZ | V34: SI/NO | AA34: CONTACTO JUEZ DE PAZ | AB34: SI/NO
B35: VI | C35: NOVEDADES RELEVANTES | H35: VI | I35: NOVEDADES RELEVANTES | N35: VI | O35: NOVEDADES RELEVANTES | T35: VI | U35: NOVEDADES RELEVANTES | Z35: VI | AA35: NOVEDADES RELEVANTES
C36: SE RETIRARON DOS CIUDADANOS POR VOLUNTAD PROPIA (SE LEVANTÓ ACTA) | I36: Describir novedad | O36: Describir novedad | U36: Describir novedad | AA36: Describir novedad
C37: SE RECIBIO UN CAPTA HUELLAS POR PARTE DEL DIPUTADO PEDRO INFANTE, CON MULTIPLES FALLAS; REGISTRO MULTIPLE DEL MISMO AFECTADO, NO IMPRIME REGISTRO PARA AUDITORIAS, NO ESPECIFICA EL CENTRO. | I37: Describir novedad | O37: Describir novedad | U37: Describir novedad | AA37: Describir novedad
C38: Describir novedad | I38: Describir novedad | O38: Describir novedad | U38: Describir novedad | AA38: Describir novedad
C39: Describir novedad | I39: Describir novedad | O39: Describir novedad | U39: Describir novedad | AA39: Describir novedad
C41: ANALISTA SAE | D41: P/I. SAMANTHA HERNÁNDEZ | I41: ANALISTA SAE | J41: PROF. XXXX | O41: ANALISTA SAE | P41: PROF. XXXX | U41: ANALISTA SAE | V41: PROF. XXXX | AA41: ANALISTA SAE | AB41: PROF. XXXX
C42: SUPERVISOR SEBIN | D42: C/G SAÚL BRISEÑO | I42: SUPERVISOR SEBIN | J42: C/G XXXXX | O42: SUPERVISOR SEBIN | P42: C/G XXXXX | U42: SUPERVISOR SEBIN | V42: C/G XXXXX | AA42: SUPERVISOR SEBIN | AB42: C/G XXXXX

Sheet CM RAFAEL AGUANA
AI2: TOTALES
C3: CENTRO: LICEO MIGUEL ANTONIO CARO | I3: CENTRO: U.E. Armando Zuloaga Blanco | O3: CENTRO: Complejo Educativo ETI Rafael Vegas | U3: CENTRO: XXXXXXXX XXXXXXXXXX XXXXXXXX | AA3: CENTRO: XXXXXXXX XXXXXXXXXX XXXXXXXX
B4: PRESENTACION | C4: TOTAL PERSONAS | D4: =D6+D7+D8+D9+D10+D11 -> 881 | H4: PRESENTACION | I4: TOTAL PERSONAS | J4: =J6+J7+J8+J9+J10+J11 -> 0 | N4: PRESENTACION | O4: TOTAL PERSONAS | P4: =P6+P7+P8+P9+P10+P11 -> 0 | T4: PRESENTACION | U4: TOTAL PERSONAS | V4: =V6+V7+V8+V9+V10+V11 -> 0 | Z4: PRESENTACION | AA4: TOTAL PERSONAS | AB4: =AB6+AB7+AB8+AB9+AB10+AB11 -> 0 | AI4: TOTAL PERSONAS | AJ4: =AJ6+AJ7+AJ8+AJ9+AJ10+AJ11 -> 881
C5: NRO. FAMILIAS | D5: 280 | I5: NRO. FAMILIAS | J5: 0 | O5: NRO. FAMILIAS | P5: 0 | U5: NRO. FAMILIAS | V5: 0 | AA5: NRO. FAMILIAS | AB5: 0 | AI5: NRO. FAMILIAS | AJ5: 280
C6: HOMBRES | D6: 204 | I6: HOMBRES | J6: 0 | O6: HOMBRES | P6: 0 | U6: HOMBRES | V6: 0 | AA6: HOMBRES | AB6: 0 | AI6: HOMBRES | AJ6: 204
C7: MUJERES | D7: 285 | I7: MUJERES | J7: 0 | O7: MUJERES | P7: 0 | U7: MUJERES | V7: 0 | AA7: MUJERES | AB7: 0 | AI7: MUJERES | AJ7: 285
C8: NIÑOS | D8: 171 | I8: NIÑOS | J8: 0 | O8: NIÑOS | P8: 0 | U8: NIÑOS | V8: 0 | AA8: NIÑOS | AB8: 0 | AI8: NIÑOS | AJ8: 171
C9: NIÑAS | D9: 194 | I9: NIÑAS | J9: 0 | O9: NIÑAS | P9: 0 | U9: NIÑAS | V9: 0 | AA9: NIÑAS | AB9: 0 | AI9: NIÑAS | AJ9: 194
C10: ADULTOS MAYORES | D10: 11 | I10: ADULTOS MAYORES | J10: 0 | O10: ADULTOS MAYORES | P10: 0 | U10: ADULTOS MAYORES | V10: 0 | AA10: ADULTOS MAYORES | AB10: 0 | AI10: ADULTOS MAYORES | AJ10: 11
C11: ADULTAS MAYORES | D11: 16 | E11: FOTO DEL CENTRO | I11: ADULTAS MAYORES | J11: 0 | K11: FOTO DEL CENTRO | O11: ADULTAS MAYORES | P11: 0 | Q11: FOTO DEL CENTRO | U11: ADULTAS MAYORES | V11: 0 | W11: FOTO DEL CENTRO | AA11: ADULTAS MAYORES | AB11: 0 | AC11: FOTO DEL CENTRO | AI11: ADULTAS MAYORES | AJ11: 16
C12: PER. CON DISCAPACIDAD | D12: 0 | I12: PER. CON DISCAPACIDAD | J12: 0 | O12: PER. CON DISCAPACIDAD | P12: 0 | U12: PER. CON DISCAPACIDAD | V12: 0 | AA12: PER. CON DISCAPACIDAD | AB12: 0 | AI12: PER. CON DISCAPACIDAD | AJ12: 0
C13: EMBARAZADAS | D13: 0 | I13: EMBARAZADAS | J13: 0 | O13: EMBARAZADAS | P13: 0 | U13: EMBARAZADAS | V13: 0 | AA13: EMBARAZADAS | AB13: 0 | AI13: EMBARAZADAS | AJ13: 0
C14: CASOS DE SALUD | D14: 0 | I14: CASOS DE SALUD | J14: 0 | O14: CASOS DE SALUD | P14: 0 | U14: CASOS DE SALUD | V14: 0 | AA14: CASOS DE SALUD | AB14: 0 | AI14: CASOS DE SALUD | AJ14: 0
C15: MASCOTAS | D15: 0 | I15: MASCOTAS | J15: 0 | O15: MASCOTAS | P15: 0 | U15: MASCOTAS | V15: 0 | AA15: MASCOTAS | AB15: 0 | AI15: MASCOTAS | AJ15: 0
B17: I | C17: ESTADO | D17: DTTO. CAPITAL | H17: I | I17: ESTADO | J17: DTTO. CAPITAL | N17: I | O17: ESTADO | P17: DTTO. CAPITAL | T17: I | U17: ESTADO | V17: DTTO. CAPITAL | Z17: I | AA17: ESTADO | AB17: DTTO. CAPITAL
C18: MUNICIPIO | D18: LIBERTADOR | I18: MUNICIPIO | J18: LIBERTADOR | O18: MUNICIPIO | P18: LIBERTADOR | U18: MUNICIPIO | V18: LIBERTADOR | AA18: MUNICIPIO | AB18: LIBERTADOR
C19: PARROQUIA | D19: SUCRE | I19: PARROQUIA | J19: SAN JOSÉ | O19: PARROQUIA | P19: SUCRE | U19: PARROQUIA | V19: XXXX | AA19: PARROQUIA | AB19: XXXX | AI19: TOTALES CENTROS | AJ19: =+AJ20+AJ21 -> 0
C20: COORDENADAS | D20: 10.5145612, - 66.939777 | I20: COORDENADAS | J20: 10°30'43.0" - 66°54'39.5" | O20: COORDENADAS | P20: 10°30'25.0" - 66°57'40.8" | U20: COORDENADAS | V20: XXXX | AA20: COORDENADAS | AB20: XXXX | AI20: OPERATIVOS
B21: II | C21: COORDINADOR POLÍTICO | D21: NAHUM FERNÁNDEZ | H21: II | I21: COORDINADOR POLÍTICO | J21: Andry Selene Aparicio V. | N21: II | O21: COORDINADOR POLÍTICO | P21: Vicemin. Francisco Fonseca | T21: II | U21: COORDINADOR POLÍTICO | V21: XXXXX XXXXXX | Z21: II | AA21: COORDINADOR POLÍTICO | AB21: XXXXX XXXXXX | AI21: EN ESPERA DE PERSONAS
C22: CEDULA | D22: 16023409 | I22: CEDULA | J22: 16320508 | O22: CEDULA | P22: XX.XXX.XXX | U22: CEDULA | V22: XX.XXX.XXX | AA22: CEDULA | AB22: XX.XXX.XXX
C23: TÉLEFONO | D23: XXXX-XXXXXXX | I23: TÉLEFONO | J23: 4129064285 | O23: TÉLEFONO | P23: 4145945228 | U23: TÉLEFONO | V23: XXXX-XXXXXXX | AA23: TÉLEFONO | AB23: XXXX-XXXXXXX
C24: ENTE A CARGO | D24: JEFE DE GOBIERNO DEL DISTRITO CAPITAL | I24: ENTE A CARGO | J24: MINISTERIO DEL PODER POPULAR PARA LA EDUCACIÓN | O24: ENTE A CARGO | P24: Ministerio del Poder Popular para la Alimentación | U24: ENTE A CARGO | V24: XXXXXXXX | AA24: ENTE A CARGO | AB24: XXXXXXXX
B25: III | C25: JEFE DE SEGURIDAD | D25: C/G EDWIN CUENCA | H25: III | I25: JEFE DE SEGURIDAD | J25: Myor Ibarra Rincón Nilsmerc | N25: III | O25: JEFE DE SEGURIDAD | P25: Cnel Humberto Arellano | T25: III | U25: JEFE DE SEGURIDAD | V25: XXXXXXX XXXXX | Z25: III | AA25: JEFE DE SEGURIDAD | AB25: XXXXXXX XXXXX
C26: CEDULA | D26: XX.XXX.XXX | I26: CEDULA | J26: 16228651 | O26: CEDULA | P26: 7827089 | U26: CEDULA | V26: XX.XXX.XXX | AA26: CEDULA | AB26: XX.XXX.XXX
C27: TÉLEFONO | D27: 4125650123 | I27: TÉLEFONO | J27: 0416.490.24.73 | O27: TÉLEFONO | P27: 4166090090 | U27: TÉLEFONO | V27: XXXX-XXXXXXX | AA27: TÉLEFONO | AB27: XXXX-XXXXXXX
C28: ORGANISMO DE SEGURIDAD | D28: PNB | I28: ORGANISMO DE SEGURIDAD | J28: DGCIM | O28: ORGANISMO DE SEGURIDAD | P28: CICPC y PNB | U28: ORGANISMO DE SEGURIDAD | V28: XXXXXX | AA28: ORGANISMO DE SEGURIDAD | AB28: XXXXXX
C29: PERSONAL A SU MANDO | D29: 150 | I29: PERSONAL A SU MANDO | J29: No transmitió la información | O29: PERSONAL A SU MANDO | P29: 23 | U29: PERSONAL A SU MANDO | V29: XX | AA29: PERSONAL A SU MANDO | AB29: XX
C30: VEHICULOS | D30: 03 VEHÍCULOS Y 40 MOTOS | I30: VEHICULOS | J30: No transmitió la información | O30: VEHICULOS | P30: 2 | U30: VEHICULOS | V30: XX | AA30: VEHICULOS | AB30: XX
B31: IV | C31: MEDICOS EN EL CENTRO | D31: SI | H31: IV | I31: MEDICOS EN EL CENTRO | J31: NO | N31: IV | O31: MEDICOS EN EL CENTRO | P31: SI | T31: IV | U31: MEDICOS EN EL CENTRO | V31: SI/NO | Z31: IV | AA31: MEDICOS EN EL CENTRO | AB31: SI/NO
C32: AMBULANCIAS | D32: NO | I32: AMBULANCIAS | J32: NO | O32: AMBULANCIAS | P32: SI | U32: AMBULANCIAS | V32: SI/NO | AA32: AMBULANCIAS | AB32: SI/NO
C33: PSICOLOGO | D33: SI | I33: PSICOLOGO | J33: NO | O33: PSICOLOGO | P33: SI | U33: PSICOLOGO | V33: SI/NO | AA33: PSICOLOGO | AB33: SI/NO
C34: CONTACTO JUEZ DE PAZ | D34: SI | I34: CONTACTO JUEZ DE PAZ | J34: SI | O34: CONTACTO JUEZ DE PAZ | P34: NO | U34: CONTACTO JUEZ DE PAZ | V34: SI/NO | AA34: CONTACTO JUEZ DE PAZ | AB34: SI/NO
B35: VI | C35: NOVEDADES RELEVANTES | H35: VI | I35: NOVEDADES RELEVANTES | N35: VI | O35: NOVEDADES RELEVANTES | T35: VI | U35: NOVEDADES RELEVANTES | Z35: VI | AA35: NOVEDADES RELEVANTES
C36: El Ministerio de Obras Públicas esta arreglando los baños del Liceo, actualmente utilizan baños portátiles en el Parque Alí Primera | I36: En espera de la llegada de los dagnificados | O36: Se espera que el plantel sea utilizado solo para personas bajo observación médica. | U36: Describir novedad | AA36: Describir novedad
C37: PDVSA les suministra la alimentación y 500 comidas preparan al frente de la Escuela | I37: Baños con deterioro | O37: Cuentan con comedor con capacidad para 400 comenzales | U37: Describir novedad | AA37: Describir novedad
C38: Tienen problemas para que les llegue el Agua Potable | O38: Carece de gas directo, solo cuentan con 2 bombonas de 18 y 01 de 43 kg | U38: Describir novedad | AA38: Describir novedad
U39: Describir novedad | AA39: Describir novedad
C41: ANALISTA SAE | D41: PROF. C. JOSÉ HERNÁNDEZ | I41: ANALISTA SAE | J41: PROF. C. JOSÉ HERNÁNDEZ | O41: ANALISTA SAE | P41: PROF. C. JOSÉ HERNÁNDEZ | U41: ANALISTA SAE | V41: PROF. XXXX | AA41: ANALISTA SAE | AB41: PROF. XXXX
C42: SUPERVISOR SEBIN | D42: C/G JOSÉ AGUANA NÚÑEZ | I42: SUPERVISOR SEBIN | J42: C/G JOSÉ AGUANA NÚÑEZ | O42: SUPERVISOR SEBIN | P42: C/G JOSÉ AGUANA NÚÑEZ | U42: SUPERVISOR SEBIN | V42: C/G XXXXX | AA42: SUPERVISOR SEBIN | AB42: C/G XXXXX

Sheet CM YOHANA CARDOZO
AI2: TOTALES
C3: CENTRO: UEN PEDRO PONTES | I3: CENTRO: UE. JOSE IGNACIO PAZ CASTILLO | O3: CENTRO: LICEO AGUSTIN AVELEDO | U3: CENTRO: ESCUELA INTERNACIONAL DE LIDERAZGO ANTONIO JOSE DE SUCRE | AA3: CENTRO: XXXXXXXX XXXXXXXXXX XXXXXXXX
B4: PRESENTACION | C4: TOTAL PERSONAS | D4: =D6+D7+D8+D9+D10+D11 -> 0 | H4: PRESENTACION | I4: TOTAL PERSONAS | J4: =J6+J7+J8+J9+J10+J11 -> 42 | N4: PRESENTACION | O4: TOTAL PERSONAS | P4: =P6+P7+P8+P9+P10+P11 -> 0 | T4: PRESENTACION | U4: TOTAL PERSONAS | V4: =V6+V7+V8+V9+V10+V11 -> 91 | Z4: PRESENTACION | AA4: TOTAL PERSONAS | AB4: =AB6+AB7+AB8+AB9+AB10+AB11 -> 0 | AI4: TOTAL PERSONAS | AJ4: =J4+P4+V4 -> 133
C5: NRO. FAMILIAS | D5: 0 | I5: NRO. FAMILIAS | J5: 8 | O5: NRO. FAMILIAS | P5: 0 | U5: NRO. FAMILIAS | V5: 37 | AA5: NRO. FAMILIAS | AB5: 0 | AI5: NRO. FAMILIAS | AJ5: =J5+P5+V5 -> 45
C6: HOMBRES | D6: 0 | I6: HOMBRES | J6: 16 | O6: HOMBRES | P6: 0 | U6: HOMBRES | V6: 24 | AA6: HOMBRES | AB6: 0 | AI6: HOMBRES | AJ6: =+J6+P6+V6 -> 40
C7: MUJERES | D7: 0 | I7: MUJERES | J7: 12 | O7: MUJERES | P7: 0 | U7: MUJERES | V7: 24 | AA7: MUJERES | AB7: 0 | AI7: MUJERES | AJ7: =+J7+P7+V7 -> 36
C8: NIÑOS | D8: 0 | I8: NIÑOS | J8: 7 | O8: NIÑOS | P8: 0 | U8: NIÑOS | V8: 19 | AA8: NIÑOS | AB8: 0 | AI8: NIÑOS | AJ8: =+J8+P8+V8 -> 26
C9: NIÑAS | D9: 0 | I9: NIÑAS | J9: 6 | O9: NIÑAS | P9: 0 | U9: NIÑAS | V9: 19 | AA9: NIÑAS | AB9: 0 | AI9: NIÑAS | AJ9: =+J9+P9+V9 -> 25
C10: ADULTOS MAYORES | D10: 0 | I10: ADULTOS MAYORES | J10: 0 | O10: ADULTOS MAYORES | P10: 0 | U10: ADULTOS MAYORES | V10: 3 | AA10: ADULTOS MAYORES | AB10: 0 | AI10: ADULTOS MAYORES | AJ10: =+J10+P10+V10 -> 3
C11: ADULTAS MAYORES | D11: 0 | E11: FOTO DEL CENTRO | I11: ADULTAS MAYORES | J11: 1 | K11: FOTO DEL CENTRO | O11: ADULTAS MAYORES | P11: 0 | Q11: FOTO DEL CENTRO | U11: ADULTAS MAYORES | V11: 2 | W11: FOTO DEL CENTRO | AA11: ADULTAS MAYORES | AB11: 0 | AC11: FOTO DEL CENTRO | AI11: ADULTAS MAYORES | AJ11: =+J11+P11+V11 -> 3
C12: PER. CON DISCAPACIDAD | D12: 0 | I12: PER. CON DISCAPACIDAD | J12: 0 | O12: PER. CON DISCAPACIDAD | P12: 0 | U12: PER. CON DISCAPACIDAD | V12: 0 | AA12: PER. CON DISCAPACIDAD | AB12: 0 | AI12: PER. CON DISCAPACIDAD | AJ12: =+J12+P12+V12 -> 0
C13: EMBARAZADAS | D13: 0 | I13: EMBARAZADAS | J13: 0 | O13: EMBARAZADAS | P13: 0 | U13: EMBARAZADAS | V13: 0 | AA13: EMBARAZADAS | AB13: 0 | AI13: EMBARAZADAS | AJ13: =+J13+P13+V13 -> 0
C14: CASOS DE SALUD | D14: 0 | I14: CASOS DE SALUD | J14: 0 | O14: CASOS DE SALUD | P14: 0 | U14: CASOS DE SALUD | V14: 0 | AA14: CASOS DE SALUD | AB14: 0 | AI14: CASOS DE SALUD | AJ14: =+J14+P14+V14 -> 0
C15: MASCOTAS | D15: 0 | I15: MASCOTAS | J15: 0 | O15: MASCOTAS | P15: 0 | U15: MASCOTAS | V15: 0 | AA15: MASCOTAS | AB15: 0 | AI15: MASCOTAS | AJ15: =+J15+P15+V15 -> 0
B17: I | C17: ESTADO | D17: DTTO. CAPITAL | H17: I | I17: ESTADO | J17: DTTO. CAPITAL | N17: I | O17: ESTADO | P17: DTTO. CAPITAL | T17: I | U17: ESTADO | V17: MIRANDA | Z17: I | AA17: ESTADO | AB17: DTTO. CAPITAL
C18: MUNICIPIO | D18: LIBERTADOR | I18: MUNICIPIO | J18: LIBERTADOR | O18: MUNICIPIO | P18: LIBERTADOR | U18: MUNICIPIO | V18: SUCRE | AA18: MUNICIPIO | AB18: LIBERTADOR
C19: PARROQUIA | D19: LA VEGA | I19: PARROQUIA | J19: LA PASTORA | O19: PARROQUIA | P19: LA PASTORA | U19: PARROQUIA | V19: FILAS DE MARICHE | AA19: PARROQUIA | AB19: XXXX | AI19: TOTALES CENTROS | AJ19: =+AJ20+AJ21 -> 0
C20: COORDENADAS | D20: 10°28'22.2"N 66°56'58.0"W | I20: COORDENADAS | J20: XXXX | O20: COORDENADAS | P20: G38H+6H9, Caracas 1010, Distrito Capital | U20: COORDENADAS | V20: 10°26'47.4"N 66°44'31.6"W | AA20: COORDENADAS | AB20: XXXX | AI20: OPERATIVOS
B21: II | C21: COORDINADOR POLÍTICO | D21: MANUEL RINCÓN | H21: II | I21: COORDINADOR POLÍTICO | J21: MILAGROS CARRILLO | N21: II | O21: COORDINADOR POLÍTICO | P21: RAMON DANIEL MANIGLIA DARWICH | T21: II | U21: COORDINADOR POLÍTICO | V21: KENEDY MORALES | Z21: II | AA21: COORDINADOR POLÍTICO | AB21: XXXXX XXXXXX | AI21: EN ESPERA DE PERSONAS
C22: CEDULA | D22: 14287553 | I22: CEDULA | J22: 15795265 | O22: CEDULA | P22: 16432329 | U22: CEDULA | V22: 20288753 | AA22: CEDULA | AB22: XX.XXX.XXX
C23: TÉLEFONO | D23: 0414-2792671 | I23: TÉLEFONO | J23: 0412-5554962 | O23: TÉLEFONO | U23: TÉLEFONO | V23: 0424-2796932 | AA23: TÉLEFONO | AB23: XXXX-XXXXXXX
C24: ENTE A CARGO | D24: CONTRALORIA GENERAL DE LA REPUBLICA | I24: ENTE A CARGO | J24: SALA DE AUTOGOBIERNO COMUNA ESTA TIERRA ES NUESTRA | O24: ENTE A CARGO | P24: PEQUIVEN | U24: ENTE A CARGO | V24: MINISTERIO DE EDUCACION Y COMUNAS | AA24: ENTE A CARGO | AB24: XXXXXXXX
B25: III | C25: JEFE DE SEGURIDAD | D25: COMISARIO RAMON ARCA | H25: III | I25: JEFE DE SEGURIDAD | J25: WILMER CISNEROS | N25: III | O25: JEFE DE SEGURIDAD | T25: III | U25: JEFE DE SEGURIDAD | V25: COMISARIO JOSE SANCHEZ | Z25: III | AA25: JEFE DE SEGURIDAD | AB25: XXXXXXX XXXXX
C26: CEDULA | D26: 13283833 | I26: CEDULA | J26: 13823585 | O26: CEDULA | U26: CEDULA | V26: 12297171 | AA26: CEDULA | AB26: XX.XXX.XXX
C27: TÉLEFONO | D27: 0414-1184886 | I27: TÉLEFONO | J27: 0412-9615675 | O27: TÉLEFONO | U27: TÉLEFONO | V27: 0412-7287070 | AA27: TÉLEFONO | AB27: XXXX-XXXXXXX
C28: ORGANISMO DE SEGURIDAD | D28: PNB | I28: ORGANISMO DE SEGURIDAD | J28: ODDI CUADRANTE DE PAZ | O28: ORGANISMO DE SEGURIDAD | U28: ORGANISMO DE SEGURIDAD | V28: PNB / POLI MIRANDA | AA28: ORGANISMO DE SEGURIDAD | AB28: XXXXXX
C29: PERSONAL A SU MANDO | D29: 10 | I29: PERSONAL A SU MANDO | J29: 30 | O29: PERSONAL A SU MANDO | U29: PERSONAL A SU MANDO | V29: 23 | AA29: PERSONAL A SU MANDO | AB29: XX
C30: VEHICULOS | D30: 5 | I30: VEHICULOS | J30: 0 | O30: VEHICULOS | U30: VEHICULOS | V30: 1 | AA30: VEHICULOS | AB30: XX
B31: IV | C31: MEDICOS EN EL CENTRO | D31: NO | H31: IV | I31: MEDICOS EN EL CENTRO | J31: NO | N31: IV | O31: MEDICOS EN EL CENTRO | P31: SI/NO | T31: IV | U31: MEDICOS EN EL CENTRO | V31: SI | Z31: IV | AA31: MEDICOS EN EL CENTRO | AB31: SI/NO
C32: AMBULANCIAS | D32: NO | I32: AMBULANCIAS | J32: NO | O32: AMBULANCIAS | P32: SI/NO | U32: AMBULANCIAS | V32: NO | AA32: AMBULANCIAS | AB32: SI/NO
C33: PSICOLOGO | D33: NO | I33: PSICOLOGO | J33: NO | O33: PSICOLOGO | P33: SI/NO | U33: PSICOLOGO | V33: SI | AA33: PSICOLOGO | AB33: SI/NO
C34: CONTACTO JUEZ DE PAZ | D34: NO | I34: CONTACTO JUEZ DE PAZ | J34: SI | O34: CONTACTO JUEZ DE PAZ | P34: SI/NO | U34: CONTACTO JUEZ DE PAZ | V34: NO | AA34: CONTACTO JUEZ DE PAZ | AB34: SI/NO
B35: VI | C35: NOVEDADES RELEVANTES | H35: VI | I35: NOVEDADES RELEVANTES | N35: VI | O35: NOVEDADES RELEVANTES | T35: VI | U35: NOVEDADES RELEVANTES | Z35: VI | AA35: NOVEDADES RELEVANTES
C36: EL CENTRO SE ENCUENTRA EN FASE DE HABILITACIÓN DE ESPACIOS | I36: DEFICIT DE INSUMOS MEDICOS, LIMPIEZA, ALIMENTACION, VENTILADORES DORMITORIOS | O36: NO TIENE EL NUM DE TLF DEL RESPONSABLE POLITICO | U36: CARENTES DE INSUMOS MEDICOS. | AA36: Describir novedad
C37: Describir novedad | I37: EL CAMPAMENTO ESTA REESTRUCTURANDO LOS BAÑOS Y HABILITANDO LA DUCHAS, INTERNET Y SERVICIO DE AGUA (TANQUES, TAMBORES Y BOMBAS DE AGUA). | O37: NO HAN DESIGNADO JEFE DE SEGURIDAD | U37: Describir novedad | AA37: Describir novedad
C38: Describir novedad | I38: Describir novedad | O38: SE MANTIENE CONTACTO CON JORGE MOTA ( 0412-7341506 / 29.622.807) Y JOEL MANGARRE ( 0414-0288030 / 10.151.257), RESPONSABLES PRESENTES EN EL LUGAR. | U38: Describir novedad | AA38: Describir novedad
C39: Describir novedad | I39: Describir novedad | O39: SE ESTAN HACIENDO ADECUCAIONES DE MANTENIMIENTO/INSTALACIONES EN EL CAMPAMENTO. | U39: Describir novedad | AA39: Describir novedad
C41: ANALISTA SAE | D41: P/COM PEREZ JONATHAN | I41: ANALISTA SAE | J41: P/COM PEREZ JONATHAN | O41: ANALISTA SAE | P41: P/COM PEREZ JONATHAN | U41: ANALISTA SAE | V41: PROF. XXXX | AA41: ANALISTA SAE | AB41: PROF. XXXX
C42: SUPERVISOR SEBIN | D42: C/G CARDOZZO | I42: SUPERVISOR SEBIN | J42: C/G CARDOZZO | O42: SUPERVISOR SEBIN | P42: C/G CARDOZZO | U42: SUPERVISOR SEBIN | V42: C/G XXXXX | AA42: SUPERVISOR SEBIN | AB42: C/G XXXXX

Sheet CG JOSE ROZO
AI2: TOTALES
C3: CENTRO: UE. JESUS ENRIQUE LOZADA | I3: CENTRO: UN. FRANCISCO PIMENTEL | O3: CENTRO: U.E.N. PEDRO EMILIO COLL | U3: CENTRO: XXXXXXXX XXXXXXXXXX XXXXXXXX | AA3: CENTRO: XXXXXXXX XXXXXXXXXX XXXXXXXX
B4: PRESENTACION | C4: TOTAL PERSONAS | D4: =D6+D7+D8+D9+D10+D11 -> 0 | H4: PRESENTACION | I4: TOTAL PERSONAS | J4: =J6+J7+J8+J9+J10+J11 -> 585 | N4: PRESENTACION | O4: TOTAL PERSONAS | P4: =P6+P7+P8+P9+P10+P11 -> 0 | T4: PRESENTACION | U4: TOTAL PERSONAS | V4: =V6+V7+V8+V9+V10+V11 -> 0 | Z4: PRESENTACION | AA4: TOTAL PERSONAS | AB4: =AB6+AB7+AB8+AB9+AB10+AB11 -> 0 | AI4: TOTAL PERSONAS | AJ4: =J4+P4+V4 -> 585
C5: NRO. FAMILIAS | D5: 0 | I5: NRO. FAMILIAS | J5: 311 | O5: NRO. FAMILIAS | P5: 0 | U5: NRO. FAMILIAS | V5: 0 | AA5: NRO. FAMILIAS | AB5: 0 | AI5: NRO. FAMILIAS | AJ5: =J5+P5+V5 -> 311
C6: HOMBRES | D6: 0 | I6: HOMBRES | J6: 121 | O6: HOMBRES | P6: 0 | U6: HOMBRES | V6: 0 | AA6: HOMBRES | AB6: 0 | AI6: HOMBRES | AJ6: =+J6+P6+V6 -> 121
C7: MUJERES | D7: 0 | I7: MUJERES | J7: 201 | O7: MUJERES | P7: 0 | U7: MUJERES | V7: 0 | AA7: MUJERES | AB7: 0 | AI7: MUJERES | AJ7: =+J7+P7+V7 -> 201
C8: NIÑOS | D8: 0 | I8: NIÑOS | J8: 106 | O8: NIÑOS | P8: 0 | U8: NIÑOS | V8: 0 | AA8: NIÑOS | AB8: 0 | AI8: NIÑOS | AJ8: =+J8+P8+V8 -> 106
C9: NIÑAS | D9: 0 | I9: NIÑAS | J9: 108 | O9: NIÑAS | P9: 0 | U9: NIÑAS | V9: 0 | AA9: NIÑAS | AB9: 0 | AI9: NIÑAS | AJ9: =+J9+P9+V9 -> 108
C10: ADULTOS MAYORES | D10: 0 | I10: ADULTOS MAYORES | J10: 12 | O10: ADULTOS MAYORES | P10: 0 | U10: ADULTOS MAYORES | V10: 0 | AA10: ADULTOS MAYORES | AB10: 0 | AI10: ADULTOS MAYORES | AJ10: =+J10+P10+V10 -> 12
C11: ADULTAS MAYORES | D11: 0 | E11: FOTO DEL CENTRO | I11: ADULTAS MAYORES | J11: 37 | K11: FOTO DEL CENTRO | O11: ADULTAS MAYORES | P11: 0 | Q11: FOTO DEL CENTRO | U11: ADULTAS MAYORES | V11: 0 | W11: FOTO DEL CENTRO | AA11: ADULTAS MAYORES | AB11: 0 | AC11: FOTO DEL CENTRO | AI11: ADULTAS MAYORES | AJ11: =+J11+P11+V11 -> 37
C12: PER. CON DISCAPACIDAD | D12: 0 | I12: PER. CON DISCAPACIDAD | J12: 0 | O12: PER. CON DISCAPACIDAD | P12: 0 | U12: PER. CON DISCAPACIDAD | V12: 0 | AA12: PER. CON DISCAPACIDAD | AB12: 0 | AI12: PER. CON DISCAPACIDAD | AJ12: =+J12+P12+V12 -> 0
C13: EMBARAZADAS | D13: 0 | I13: EMBARAZADAS | J13: 0 | O13: EMBARAZADAS | P13: 0 | U13: EMBARAZADAS | V13: 0 | AA13: EMBARAZADAS | AB13: 0 | AI13: EMBARAZADAS | AJ13: =+J13+P13+V13 -> 0
C14: CASOS DE SALUD | D14: 0 | I14: CASOS DE SALUD | J14: 0 | O14: CASOS DE SALUD | P14: 0 | U14: CASOS DE SALUD | V14: 0 | AA14: CASOS DE SALUD | AB14: 0 | AI14: CASOS DE SALUD | AJ14: =+J14+P14+V14 -> 0
C15: MASCOTAS | D15: 0 | I15: MASCOTAS | J15: 0 | O15: MASCOTAS | P15: 0 | U15: MASCOTAS | V15: 0 | AA15: MASCOTAS | AB15: 0 | AI15: MASCOTAS | AJ15: =+J15+P15+V15 -> 0
B17: I | C17: ESTADO | D17: DTTO. CAPITAL | H17: I | I17: ESTADO | J17: DTTO. CAPITAL | N17: I | O17: ESTADO | P17: DTTO. CAPITAL | T17: I | U17: ESTADO | V17: DTTO. CAPITAL | Z17: I | AA17: ESTADO | AB17: DTTO. CAPITAL
C18: MUNICIPIO | D18: LIBERTADOR | I18: MUNICIPIO | J18: LIBERTADOR | O18: MUNICIPIO | P18: LIBERTADOR | U18: MUNICIPIO | V18: LIBERTADOR | AA18: MUNICIPIO | AB18: LIBERTADOR
C19: PARROQUIA | D19: EL RECREO | I19: PARROQUIA | J19: STA. TERESA | O19: PARROQUIA | P19: COCHE | U19: PARROQUIA | V19: XXXX | AA19: PARROQUIA | AB19: XXXX | AI19: TOTALES CENTROS | AJ19: =+AJ20+AJ21 -> 3
C20: COORDENADAS | D20: 10° 30' 13" LN 66° 52' 10" LO | I20: COORDENADAS | J20: 10° 29' 47" LN. 66° 55' 5" LO | O20: COORDENADAS | P20: 10.4508° N, 66.9227° O | U20: COORDENADAS | V20: XXXX | AA20: COORDENADAS | AB20: XXXX | AI20: OPERATIVOS | AJ20: 1
B21: II | C21: COORDINADOR POLÍTICO | D21: ANGEL BLANCO | H21: II | I21: COORDINADOR POLÍTICO | J21: NORLAN RAMOS | N21: II | O21: COORDINADOR POLÍTICO | P21: LUISA DAYANA MARTÍNEZ | T21: II | U21: COORDINADOR POLÍTICO | V21: XXXXX XXXXXX | Z21: II | AA21: COORDINADOR POLÍTICO | AB21: XXXXX XXXXXX | AI21: EN ESPERA DE PERSONAS | AJ21: 2
C22: CEDULA | D22: 15701930 | I22: CEDULA | J22: 23639410 | O22: CEDULA | P22: 12085619 | U22: CEDULA | V22: XX.XXX.XXX | AA22: CEDULA | AB22: XX.XXX.XXX
C23: TÉLEFONO | D23: 0424-1465948 | I23: TÉLEFONO | J23: 0412-9046707 | O23: TÉLEFONO | P23: 0412-5930036 | U23: TÉLEFONO | V23: XXXX-XXXXXXX | AA23: TÉLEFONO | AB23: XXXX-XXXXXXX
C24: ENTE A CARGO | D24: MINISTERIO DE COMERCIO EXTERIOR | I24: ENTE A CARGO | J24: SENIAT | O24: ENTE A CARGO | P24: MINISTERIO DEL PODER POPULAR PARA LA EDUCACIÓN | U24: ENTE A CARGO | V24: XXXXXXXX | AA24: ENTE A CARGO | AB24: XXXXXXXX
B25: III | C25: JEFE DE SEGURIDAD | D25: CJ ESPARTACO HERMANDEZ | H25: III | I25: JEFE DE SEGURIDAD | J25: CNEL. HENRY CUBILLAN | N25: III | O25: JEFE DE SEGURIDAD | P25: CAP. PÉREZ PÉREZ GERALD | T25: III | U25: JEFE DE SEGURIDAD | V25: XXXXXXX XXXXX | Z25: III | AA25: JEFE DE SEGURIDAD | AB25: XXXXXXX XXXXX
C26: CEDULA | D26: 13463285 | I26: CEDULA | J26: 15714816 | O26: CEDULA | P26: 19606799 | U26: CEDULA | V26: XX.XXX.XXX | AA26: CEDULA | AB26: XX.XXX.XXX
C27: TÉLEFONO | D27: 0424-2090472 | I27: TÉLEFONO | J27: 0414-6514656 | O27: TÉLEFONO | P27: 0416-9492603 | U27: TÉLEFONO | V27: XXXX-XXXXXXX | AA27: TÉLEFONO | AB27: XXXX-XXXXXXX
C28: ORGANISMO DE SEGURIDAD | D28: SEBIN | I28: ORGANISMO DE SEGURIDAD | J28: GNB | O28: ORGANISMO DE SEGURIDAD | P28: GNB | U28: ORGANISMO DE SEGURIDAD | V28: XXXXXX | AA28: ORGANISMO DE SEGURIDAD | AB28: XXXXXX
C29: PERSONAL A SU MANDO | D29: 9 | I29: PERSONAL A SU MANDO | J29: 20 | O29: PERSONAL A SU MANDO | P29: 16 | U29: PERSONAL A SU MANDO | V29: XX | AA29: PERSONAL A SU MANDO | AB29: XX
C30: VEHICULOS | D30: 1 | I30: VEHICULOS | J30: 1 | O30: VEHICULOS | P30: 0 | U30: VEHICULOS | V30: XX | AA30: VEHICULOS | AB30: XX
B31: IV | C31: MEDICOS EN EL CENTRO | D31: NO | H31: IV | I31: MEDICOS EN EL CENTRO | J31: SI | N31: IV | O31: MEDICOS EN EL CENTRO | P31: SI | T31: IV | U31: MEDICOS EN EL CENTRO | V31: SI/NO | Z31: IV | AA31: MEDICOS EN EL CENTRO | AB31: SI/NO
C32: AMBULANCIAS | D32: NO | I32: AMBULANCIAS | J32: SI | O32: AMBULANCIAS | P32: SI | U32: AMBULANCIAS | V32: SI/NO | AA32: AMBULANCIAS | AB32: SI/NO
C33: PSICOLOGO | D33: NO | I33: PSICOLOGO | J33: SI | O33: PSICOLOGO | P33: SI | U33: PSICOLOGO | V33: SI/NO | AA33: PSICOLOGO | AB33: SI/NO
C34: CONTACTO JUEZ DE PAZ | D34: NO | I34: CONTACTO JUEZ DE PAZ | J34: NO | O34: CONTACTO JUEZ DE PAZ | P34: NO | U34: CONTACTO JUEZ DE PAZ | V34: SI/NO | AA34: CONTACTO JUEZ DE PAZ | AB34: SI/NO
B35: VI | C35: NOVEDADES RELEVANTES | H35: VI | I35: NOVEDADES RELEVANTES | N35: VI | O35: NOVEDADES RELEVANTES | T35: VI | U35: NOVEDADES RELEVANTES | Z35: VI | AA35: NOVEDADES RELEVANTES
C36: FALTA DE COORDINACION PARA LA ALIMENTACION DEL PERSONAL DE SEGURIDAD. | I36: Describir novedad | O36: NOMBRE DEL JEFE DE SEGURIDAD CORONEL LEONARDO MALAGUERA, ESTE DESIGNA RESPONSABLE AL CAPITAN PÉREZ PÉREZ GERALD. | U36: Describir novedad | AA36: Describir novedad
C37: HAY COLCHONES PERO NO HAN LLEGADO LAS LITERAS. | I37: Describir novedad | O37: VEHICCULOS DEL COMANDO RURAL GNB 43-1 EL HATILLO. | U37: Describir novedad | AA37: Describir novedad
C38: TRABAJOS EN ELECTRICIDAD Y BAÑOS. | I38: Describir novedad | O38: BAÑOS PRINCIPALES ESTÁN EN FASE DE CONSTRUCCIÓN. | U38: Describir novedad | AA38: Describir novedad
C39: Describir novedad | I39: Describir novedad | O39: Describir novedad | U39: Describir novedad | AA39: Describir novedad
C41: ANALISTA SAE | D41: P/COM PEREZ JONATHAN | I41: ANALISTA SAE | J41: P/COM PEREZ JONATHAN | O41: ANALISTA SAE | P41: P/COM PEREZ JONATHAN | U41: ANALISTA SAE | V41: PROF. XXXX | AA41: ANALISTA SAE | AB41: PROF. XXXX
C42: SUPERVISOR SEBIN | D42: C/G JOSE ROZO | I42: SUPERVISOR SEBIN | J42: C/G JOSE ROZO | O42: SUPERVISOR SEBIN | P42: C/G JOSE ROZO | U42: SUPERVISOR SEBIN | V42: C/G XXXXX | AA42: SUPERVISOR SEBIN | AB42: C/G XXXXX

Sheet CG CARLOS CONTRERAS
AI2: TOTALES
C3: CENTRO: UNIDAD EDUCATIVA NACIONAL CONOPOIMA | I3: CENTRO: UNIDAD EDUCATIVA NACIONAL LINO DE CLEMENTE | O3: CENTRO: UEN EL LIBERTADOR | U3: CENTRO: UNIDAD EDUCATIVA NACIONAL JESÚS MARIA ALFARO ZAMORA | AA3: CENTRO: XXXXXXXX XXXXXXXXXX XXXXXXXX
B4: PRESENTACION | C4: TOTAL PERSONAS | D4: =D6+D7+D8+D9+D10+D11 -> 0 | H4: PRESENTACION | I4: TOTAL PERSONAS | J4: =J6+J7+J8+J9+J10+J11 -> 0 | N4: PRESENTACION | O4: TOTAL PERSONAS | P4: =P6+P7+P8+P9+P10+P11 -> 0 | T4: PRESENTACION | U4: TOTAL PERSONAS | V4: =V6+V7+V8+V9+V10+V11 -> 0 | Z4: PRESENTACION | AA4: TOTAL PERSONAS | AB4: =AB6+AB7+AB8+AB9+AB10+AB11 -> 0 | AI4: TOTAL PERSONAS | AJ4: =J4+P4+V4 -> 0
C5: NRO. FAMILIAS | D5: 0 | I5: NRO. FAMILIAS | J5: 0 | O5: NRO. FAMILIAS | P5: 0 | U5: NRO. FAMILIAS | V5: 0 | AA5: NRO. FAMILIAS | AB5: 0 | AI5: NRO. FAMILIAS | AJ5: =J5+P5+V5 -> 0
C6: HOMBRES | D6: 0 | I6: HOMBRES | J6: 0 | O6: HOMBRES | P6: 0 | U6: HOMBRES | V6: 0 | AA6: HOMBRES | AB6: 0 | AI6: HOMBRES | AJ6: =+J6+P6+V6 -> 0
C7: MUJERES | D7: 0 | I7: MUJERES | J7: 0 | O7: MUJERES | P7: 0 | U7: MUJERES | V7: 0 | AA7: MUJERES | AB7: 0 | AI7: MUJERES | AJ7: =+J7+P7+V7 -> 0
C8: NIÑOS | D8: 0 | I8: NIÑOS | J8: 0 | O8: NIÑOS | P8: 0 | U8: NIÑOS | V8: 0 | AA8: NIÑOS | AB8: 0 | AI8: NIÑOS | AJ8: =+J8+P8+V8 -> 0
C9: NIÑAS | D9: 0 | I9: NIÑAS | J9: 0 | O9: NIÑAS | P9: 0 | U9: NIÑAS | V9: 0 | AA9: NIÑAS | AB9: 0 | AI9: NIÑAS | AJ9: =+J9+P9+V9 -> 0
C10: ADULTOS MAYORES | D10: 0 | I10: ADULTOS MAYORES | J10: 0 | O10: ADULTOS MAYORES | P10: 0 | U10: ADULTOS MAYORES | V10: 0 | AA10: ADULTOS MAYORES | AB10: 0 | AI10: ADULTOS MAYORES | AJ10: =+J10+P10+V10 -> 0
C11: ADULTAS MAYORES | D11: 0 | E11: FOTO DEL CENTRO | I11: ADULTAS MAYORES | J11: 0 | K11: FOTO DEL CENTRO | O11: ADULTAS MAYORES | P11: 0 | Q11: FOTO DEL CENTRO | U11: ADULTAS MAYORES | V11: 0 | W11: FOTO DEL CENTRO | AA11: ADULTAS MAYORES | AB11: 0 | AC11: FOTO DEL CENTRO | AI11: ADULTAS MAYORES | AJ11: =+J11+P11+V11 -> 0
C12: PER. CON DISCAPACIDAD | D12: 0 | I12: PER. CON DISCAPACIDAD | J12: 0 | O12: PER. CON DISCAPACIDAD | P12: 0 | U12: PER. CON DISCAPACIDAD | V12: 0 | AA12: PER. CON DISCAPACIDAD | AB12: 0 | AI12: PER. CON DISCAPACIDAD | AJ12: =+J12+P12+V12 -> 0
C13: EMBARAZADAS | D13: 0 | I13: EMBARAZADAS | J13: 0 | O13: EMBARAZADAS | P13: 0 | U13: EMBARAZADAS | V13: 0 | AA13: EMBARAZADAS | AB13: 0 | AI13: EMBARAZADAS | AJ13: =+J13+P13+V13 -> 0
C14: CASOS DE SALUD | D14: 0 | I14: CASOS DE SALUD | J14: 0 | O14: CASOS DE SALUD | P14: 0 | U14: CASOS DE SALUD | V14: 0 | AA14: CASOS DE SALUD | AB14: 0 | AI14: CASOS DE SALUD | AJ14: =+J14+P14+V14 -> 0
C15: MASCOTAS | D15: 0 | I15: MASCOTAS | J15: 0 | O15: MASCOTAS | P15: 0 | U15: MASCOTAS | V15: 0 | AA15: MASCOTAS | AB15: 0 | AI15: MASCOTAS | AJ15: =+J15+P15+V15 -> 0
B17: I | C17: ESTADO | D17: DTTO. CAPITAL | H17: I | I17: ESTADO | J17: DTTO. CAPITAL | N17: I | O17: ESTADO | P17: DTTO. CAPITAL | T17: I | U17: ESTADO | V17: DTTO. CAPITAL | Z17: I | AA17: ESTADO | AB17: DTTO. CAPITAL
C18: MUNICIPIO | D18: LIBERTADOR | I18: MUNICIPIO | J18: LIBERTADOR | O18: MUNICIPIO | P18: LIBERTADOR | U18: MUNICIPIO | V18: LIBERTADOR | AA18: MUNICIPIO | AB18: LIBERTADOR
C19: PARROQUIA | D19: EL HATILLO | I19: PARROQUIA | J19: BARUTA | O19: PARROQUIA | P19: CHACAO | U19: PARROQUIA | V19: CAFETAL | AA19: PARROQUIA | AB19: XXXX | AI19: TOTALES CENTROS | AJ19: =+AJ20+AJ21 -> 0
C20: COORDENADAS | D20: 10.423575,-66.821548 | I20: COORDENADAS | J20: 10°27'31.1N y 66°51'56.3W | O20: COORDENADAS | P20: 10°30,29''N,66°06''O | U20: COORDENADAS | V20: 10.464064,-66.832184 | AA20: COORDENADAS | AB20: XXXX | AI20: OPERATIVOS
B21: II | C21: COORDINADOR POLÍTICO | D21: MARÍA BELLY | H21: II | I21: COORDINADOR POLÍTICO | J21: JOSE CONTRERAS | N21: II | O21: COORDINADOR POLÍTICO | P21: CRISMER LAUCHO | T21: II | U21: COORDINADOR POLÍTICO | V21: YARISOL BERRIOS | Z21: II | AA21: COORDINADOR POLÍTICO | AB21: XXXXX XXXXXX | AI21: EN ESPERA DE PERSONAS
C22: CEDULA | D22: 8649914 | I22: CEDULA | J22: 33968532 | O22: CEDULA | P22: 13432322 | U22: CEDULA | V22: 13564199 | AA22: CEDULA | AB22: XX.XXX.XXX
C23: TÉLEFONO | D23: 0412-9203517 | I23: TÉLEFONO | J23: 4241875291 | O23: TÉLEFONO | P23: 4144668829 | U23: TÉLEFONO | V23: 0412-9906973 | AA23: TÉLEFONO | AB23: XXXX-XXXXXXX
C24: ENTE A CARGO | D24: SUPERINTENDENCIA DE LA ACTIVIDAD ASEGURADORA (SUDIASEG) | I24: ENTE A CARGO | J24: INSTITUTO VENEZOLANO DE LOS SEGUROS SOCIALES (IVSS) | O24: ENTE A CARGO | P24: MINISTERIO DE HÁBITAT Y VIVIENDA | U24: ENTE A CARGO | V24: INSTITUTO NACIONAL DE LOS ESPACIOS ACUATICOS. | AA24: ENTE A CARGO | AB24: XXXXXXXX
B25: III | C25: JEFE DE SEGURIDAD | H25: III | I25: JEFE DE SEGURIDAD | N25: III | O25: JEFE DE SEGURIDAD | T25: III | U25: JEFE DE SEGURIDAD | Z25: III | AA25: JEFE DE SEGURIDAD | AB25: XXXXXXX XXXXX
C26: CEDULA | I26: CEDULA | O26: CEDULA | U26: CEDULA | AA26: CEDULA | AB26: XX.XXX.XXX
C27: TÉLEFONO | I27: TÉLEFONO | O27: TÉLEFONO | U27: TÉLEFONO | AA27: TÉLEFONO | AB27: XXXX-XXXXXXX
C28: ORGANISMO DE SEGURIDAD | I28: ORGANISMO DE SEGURIDAD | O28: ORGANISMO DE SEGURIDAD | U28: ORGANISMO DE SEGURIDAD | AA28: ORGANISMO DE SEGURIDAD | AB28: XXXXXX
C29: PERSONAL A SU MANDO | D29: XX | I29: PERSONAL A SU MANDO | O29: PERSONAL A SU MANDO | U29: PERSONAL A SU MANDO | AA29: PERSONAL A SU MANDO | AB29: XX
C30: VEHICULOS | D30: XX | I30: VEHICULOS | O30: VEHICULOS | U30: VEHICULOS | AA30: VEHICULOS | AB30: XX
B31: IV | C31: MEDICOS EN EL CENTRO | D31: SI | H31: IV | I31: MEDICOS EN EL CENTRO | J31: NO | N31: IV | O31: MEDICOS EN EL CENTRO | P31: NO | T31: IV | U31: MEDICOS EN EL CENTRO | V31: NO | Z31: IV | AA31: MEDICOS EN EL CENTRO | AB31: SI/NO
C32: AMBULANCIAS | D32: SI | I32: AMBULANCIAS | J32: NO | O32: AMBULANCIAS | P32: NO | U32: AMBULANCIAS | V32: NO | AA32: AMBULANCIAS | AB32: SI/NO
C33: PSICOLOGO | D33: NO | I33: PSICOLOGO | J33: SI | O33: PSICOLOGO | P33: NO | U33: PSICOLOGO | V33: NO | AA33: PSICOLOGO | AB33: SI/NO
C34: CONTACTO JUEZ DE PAZ | D34: SI | I34: CONTACTO JUEZ DE PAZ | J34: SI | O34: CONTACTO JUEZ DE PAZ | P34: SI | U34: CONTACTO JUEZ DE PAZ | V34: NO | AA34: CONTACTO JUEZ DE PAZ | AB34: SI/NO
B35: VI | C35: NOVEDADES RELEVANTES | H35: VI | I35: NOVEDADES RELEVANTES | N35: VI | O35: NOVEDADES RELEVANTES | T35: VI | U35: NOVEDADES RELEVANTES | Z35: VI | AA35: NOVEDADES RELEVANTES
C36: NO CUENTA CON PERSONAL DE SEGURIDAD ASIGNADO | I36: NO CUENTA CON PERSONAL DE SEGURIDAD ASIGNADO | O36: NO SE CONSIDERA APTO PARA REFUGIO | U36: FRACTURA EN LOS TANQUES DE AGUA | AA36: Describir novedad
C37: NO CUENTA CON CAMAS NI COBIJAS (SOLO COLCHONES) | I37: ZONA IDE ALTA PELIGROSIDAD | O37: NO CUENTA CON PERSONAL DE SEGURIDAD ASIGNADO | U37: FUGA DE GAS EN LA COCINA | AA37: Describir novedad
C38: NO CUENTA CON DUCHAS | I38: FALLAS DE ALUMBRADO PÚBLICO | O38: Describir novedad | U38: NO CUENTA CON PERSONAL DE SEGURIDAD ASIGNADO | AA38: Describir novedad
C39: SERVICIO DE AGUA RACIONADO ( MIERCOLES A DOMINGO) | I39: ZONA DE OPOSICIÓN | O39: Describir novedad | AA39: Describir novedad
C41: ANALISTA SAE | D41: P/I SAMANTHA HERNÁNDEZ | I41: ANALISTA SAE | J41: P/I SAMANTHA HERNÁNDEZ | O41: ANALISTA SAE | P41: P/I SAMANTHA HERNÁNDEZ | U41: ANALISTA SAE | V41: P/I SAMANTHA HERNÁNDEZ | AA41: ANALISTA SAE | AB41: PROF. XXXX
C42: SUPERVISOR SEBIN | D42: C/J LEIDY BRISEÑO | I42: SUPERVISOR SEBIN | J42: COM. WIZULEIDYS MÚJICA | O42: SUPERVISOR SEBIN | P42: COM. WENDY SANTAELLA | U42: SUPERVISOR SEBIN | V42: COM. KELY SANTIAGO | AA42: SUPERVISOR SEBIN | AB42: C/G XXXXX

Sheet CG JOSE MARTINEZ
AI2: TOTALES
C3: CENTRO: CEN ANA MARÍA CAMPOS | I3: CENTRO: CEN MARISCAL SUCRE | O3: CENTRO: UNIDAD EDUC. ESTADAL FRANCISCO IZNARDI | U3: CENTRO: UEN DR. JOSÉ DE JESÚS AROCHA | AA3: CENTRO: XXXXXXXX XXXXXXXXXX XXXXXXXX
B4: PRESENTACION | C4: TOTAL PERSONAS | D4: =D6+D7+D8+D9+D10+D11 -> 0 | H4: PRESENTACION | I4: TOTAL PERSONAS | J4: =J6+J7+J8+J9+J10+J11 -> 0 | N4: PRESENTACION | O4: TOTAL PERSONAS | P4: =P6+P7+P8+P9+P10+P11 -> 0 | T4: PRESENTACION | U4: TOTAL PERSONAS | V4: =V6+V7+V8+V9+V10+V11 -> 0 | Z4: PRESENTACION | AA4: TOTAL PERSONAS | AB4: =AB6+AB7+AB8+AB9+AB10+AB11 -> 0 | AI4: TOTAL PERSONAS | AJ4: =J4+P4+V4 -> 0
C5: NRO. FAMILIAS | D5: 0 | I5: NRO. FAMILIAS | J5: 0 | O5: NRO. FAMILIAS | P5: 0 | U5: NRO. FAMILIAS | V5: 0 | AA5: NRO. FAMILIAS | AB5: 0 | AI5: NRO. FAMILIAS | AJ5: =J5+P5+V5 -> 0
C6: HOMBRES | D6: 0 | I6: HOMBRES | J6: 0 | O6: HOMBRES | P6: 0 | U6: HOMBRES | V6: 0 | AA6: HOMBRES | AB6: 0 | AI6: HOMBRES | AJ6: =+J6+P6+V6 -> 0
C7: MUJERES | D7: 0 | I7: MUJERES | J7: 0 | O7: MUJERES | P7: 0 | U7: MUJERES | V7: 0 | AA7: MUJERES | AB7: 0 | AI7: MUJERES | AJ7: =+J7+P7+V7 -> 0
C8: NIÑOS | D8: 0 | I8: NIÑOS | J8: 0 | O8: NIÑOS | P8: 0 | U8: NIÑOS | V8: 0 | AA8: NIÑOS | AB8: 0 | AI8: NIÑOS | AJ8: =+J8+P8+V8 -> 0
C9: NIÑAS | D9: 0 | I9: NIÑAS | J9: 0 | O9: NIÑAS | P9: 0 | U9: NIÑAS | V9: 0 | AA9: NIÑAS | AB9: 0 | AI9: NIÑAS | AJ9: =+J9+P9+V9 -> 0
C10: ADULTOS MAYORES | D10: 0 | I10: ADULTOS MAYORES | J10: 0 | O10: ADULTOS MAYORES | P10: 0 | U10: ADULTOS MAYORES | V10: 0 | AA10: ADULTOS MAYORES | AB10: 0 | AI10: ADULTOS MAYORES | AJ10: =+J10+P10+V10 -> 0
C11: ADULTAS MAYORES | D11: 0 | E11: FOTO DEL CENTRO | I11: ADULTAS MAYORES | J11: 0 | K11: FOTO DEL CENTRO | O11: ADULTAS MAYORES | P11: 0 | Q11: FOTO DEL CENTRO | U11: ADULTAS MAYORES | V11: 0 | W11: FOTO DEL CENTRO | AA11: ADULTAS MAYORES | AB11: 0 | AC11: FOTO DEL CENTRO | AI11: ADULTAS MAYORES | AJ11: =+J11+P11+V11 -> 0
C12: PER. CON DISCAPACIDAD | D12: 0 | I12: PER. CON DISCAPACIDAD | J12: 0 | O12: PER. CON DISCAPACIDAD | P12: 0 | U12: PER. CON DISCAPACIDAD | V12: 0 | AA12: PER. CON DISCAPACIDAD | AB12: 0 | AI12: PER. CON DISCAPACIDAD | AJ12: =+J12+P12+V12 -> 0
C13: EMBARAZADAS | D13: 0 | I13: EMBARAZADAS | J13: 0 | O13: EMBARAZADAS | P13: 0 | U13: EMBARAZADAS | V13: 0 | AA13: EMBARAZADAS | AB13: 0 | AI13: EMBARAZADAS | AJ13: =+J13+P13+V13 -> 0
C14: CASOS DE SALUD | D14: 0 | I14: CASOS DE SALUD | J14: 0 | O14: CASOS DE SALUD | P14: 0 | U14: CASOS DE SALUD | V14: 0 | AA14: CASOS DE SALUD | AB14: 0 | AI14: CASOS DE SALUD | AJ14: =+J14+P14+V14 -> 0
C15: MASCOTAS | D15: 0 | I15: MASCOTAS | J15: 0 | O15: MASCOTAS | P15: 0 | U15: MASCOTAS | V15: 0 | AA15: MASCOTAS | AB15: 0 | AI15: MASCOTAS | AJ15: =+J15+P15+V15 -> 0
B17: I | C17: ESTADO | D17: MIRANDA | H17: I | I17: ESTADO | J17: MIRANDA | N17: I | O17: ESTADO | P17: MIRANDA | T17: I | U17: ESTADO | V17: MIRANDA | Z17: I | AA17: ESTADO | AB17: DTTO. CAPITAL
C18: MUNICIPIO | D18: SUCRE | I18: MUNICIPIO | J18: SUCRE | O18: MUNICIPIO | P18: SUCRE | U18: MUNICIPIO | V18: SUCRE | AA18: MUNICIPIO | AB18: LIBERTADOR
C19: PARROQUIA | D19: FILAS DE MARICHE | I19: PARROQUIA | J19: LA DOLORITA | O19: PARROQUIA | P19: PETARE | U19: PARROQUIA | V19: PETARE | AA19: PARROQUIA | AB19: XXXX | AI19: TOTALES CENTROS | AJ19: =+AJ20+AJ21 -> 0
C20: COORDENADAS | D20: 10.4484739,-66.7445583,16 | I20: COORDENADAS | J20: 10.4620216-66.7630672 | O20: COORDENADAS | P20: 10.4589414-66.7575537 | U20: COORDENADAS | V20: 10.4767121,-66.8064085 | AA20: COORDENADAS | AB20: XXXX | AI20: OPERATIVOS
B21: II | C21: COORDINADOR POLÍTICO | D21: JOSÉ VICENTE RANGEL S. | H21: II | I21: COORDINADOR POLÍTICO | J21: CNEL (EJB) JOSÉ ZAMBRANO | N21: II | O21: COORDINADOR POLÍTICO | P21: ANA KATIUSCA LEÓN TORRES | T21: II | U21: COORDINADOR POLÍTICO | V21: GABRIELA BERRIOS | Z21: II | AA21: COORDINADOR POLÍTICO | AB21: XXXXX XXXXXX | AI21: EN ESPERA DE PERSONAS
C22: CEDULA | D22: V-16.876.384 | I22: CEDULA | J22: V-13.468.262 | O22: CEDULA | P22: V-11.689.472 | U22: CEDULA | V22: SE PROCESA | AA22: CEDULA | AB22: XX.XXX.XXX
C23: TÉLEFONO | D23: 0414-3298498 | I23: TÉLEFONO | J23: 0416-6135483 | O23: TÉLEFONO | P23: 0424-1697101 | U23: TÉLEFONO | V23: 0412-6051385 | AA23: TÉLEFONO | AB23: XXXX-XXXXXXX
C24: ENTE A CARGO | D24: INST. MUNIC. AUTÓNOMO DE PROTECC. SANEAM. (IMAPSAS) | I24: ENTE A CARGO | J24: MINISTERIO DEL PODER POPULAR PARA INDUSTRIA Y COMERCIO | O24: ENTE A CARGO | P24: CONSEJO LEGISLATIVO DEL ESTADO MIRANDA | U24: ENTE A CARGO | V24: CORPOELEC | AA24: ENTE A CARGO | AB24: XXXXXXXX
B25: III | C25: JEFE DE SEGURIDAD | D25: POR DESIGNAR | H25: III | I25: JEFE DE SEGURIDAD | J25: COMISARIO JOSÉ ARIAS | N25: III | O25: JEFE DE SEGURIDAD | P25: I/J SALANDI DRAIMER | T25: III | U25: JEFE DE SEGURIDAD | V25: I/J OGLIS AGUIRRE | Z25: III | AA25: JEFE DE SEGURIDAD | AB25: XXXXXXX XXXXX
C26: CEDULA | D26: XX.XXX.XXX | I26: CEDULA | J26: XX.XXX.XXX | O26: CEDULA | P26: V-15.758.276 | U26: CEDULA | V26: SE PROCESA | AA26: CEDULA | AB26: XX.XXX.XXX
C27: TÉLEFONO | D27: XXXX-XXXXXXX | I27: TÉLEFONO | J27: XXXX-XXXXXXX | O27: TÉLEFONO | P27: 4128269486 | U27: TÉLEFONO | V27: 0414-3967801 | AA27: TÉLEFONO | AB27: XXXX-XXXXXXX
C28: ORGANISMO DE SEGURIDAD | D28: POLICÍA MUNICIPAL DE SUCRE | I28: ORGANISMO DE SEGURIDAD | J28: ALCALDÍA DEL MUNICIPIO SUCRE | O28: ORGANISMO DE SEGURIDAD | P28: POLIMIRANDA | U28: ORGANISMO DE SEGURIDAD | V28: POLISUCRE | AA28: ORGANISMO DE SEGURIDAD | AB28: XXXXXX
C29: PERSONAL A SU MANDO | D29: POR ASIGNAR | I29: PERSONAL A SU MANDO | J29: XX | O29: PERSONAL A SU MANDO | P29: 2 | U29: PERSONAL A SU MANDO | V29: 3 | AA29: PERSONAL A SU MANDO | AB29: XX
C30: VEHICULOS | D30: POR ASIGNAR | I30: VEHICULOS | J30: XX | O30: VEHICULOS | P30: 1 | U30: VEHICULOS | V30: NINGUNO | AA30: VEHICULOS | AB30: XX
B31: IV | C31: MEDICOS EN EL CENTRO | D31: POR DESIGNAR | H31: IV | I31: MEDICOS EN EL CENTRO | J31: POR DESIGNAR | N31: IV | O31: MEDICOS EN EL CENTRO | P31: POR DESIGNAR | T31: IV | U31: MEDICOS EN EL CENTRO | V31: POR DESIGNAR | Z31: IV | AA31: MEDICOS EN EL CENTRO | AB31: SI/NO
C32: AMBULANCIAS | D32: NO | I32: AMBULANCIAS | J32: NO | O32: AMBULANCIAS | P32: NO | U32: AMBULANCIAS | V32: NO | AA32: AMBULANCIAS | AB32: SI/NO
C33: PSICOLOGO | D33: NO | I33: PSICOLOGO | J33: NO | O33: PSICOLOGO | P33: NO | U33: PSICOLOGO | V33: NO | AA33: PSICOLOGO | AB33: SI/NO
C34: CONTACTO JUEZ DE PAZ | D34: NO | I34: CONTACTO JUEZ DE PAZ | J34: NO | O34: CONTACTO JUEZ DE PAZ | P34: NO | U34: CONTACTO JUEZ DE PAZ | V34: NO | AA34: CONTACTO JUEZ DE PAZ | AB34: SI/NO
B35: VI | C35: NOVEDADES RELEVANTES | H35: VI | I35: NOVEDADES RELEVANTES | N35: VI | O35: NOVEDADES RELEVANTES | T35: VI | U35: NOVEDADES RELEVANTES | Z35: VI | AA35: NOVEDADES RELEVANTES
C36: CAPACIDAD PARA 200 PERSONAS, SE PREVE RECIBIR A 120 PERSONAS | I36: CENTRO NO APTO, SIN CONDICIONES DE SEGURIDAD | O36: LA SUDEBAN, ES LA ENCARGADA DEL SUMINISTRO LOGÍSTICO | U36: CENTRO EN FASE DE ACONDICIONAMIENTO | AA36: Describir novedad
C37: INSTALACIONES EN FASE DE ACONDICIONAMIENTO, SE ESPERA LLEGADA DE ENSERES E INSUMOS. | I37: CENTRO EN FASE DE ACONDICIONAMIENTO | O37: CENTRO TRANSITORIO EN FASE DE ACONDICIONAMIENTO | U37: PREVE RECIBIR 50 PERSONAS | AA37: Describir novedad
C38: CAPTAHUELLAS ASIGNADOS AL COORDINADOR POLITICO | I38: FACHADAS Y PAREDES AFECTADAS DURANTE LOS TERREMOTOS | O38: NO CUENTA CON EL SERVICIO DE ELECTRICIDAD Y ESTÁN TRABAJANDO PARA REESTABLECERLO. | U38: FUERON ASIGNADOS LOS CAPTAHUELLAS | AA38: Describir novedad
C39: ASEGURAMIENTO ESTARÁ A CARGO DE 10 FUNCIONARIOS DE POLISUCRE | I39: Describir novedad | O39: CAPACIDAD PARA ATENDER 150 PERSONAS, SE ESPERA RECIBIR ENTRE 120 Y 150 PERSONAS | U39: Describir novedad | AA39: Describir novedad
C41: ANALISTA SAE | D41: PROF. MARVIN OSIO | I41: ANALISTA SAE | J41: PROF. MARVIN OSIO | O41: ANALISTA SAE | P41: PROF. MARVIN OSIO | U41: ANALISTA SAE | V41: PROF. MARVIN OSIO | AA41: ANALISTA SAE | AB41: PROF. XXXX
C42: SUPERVISOR SEBIN | D42: P/C ROYLAD BELISARIO | I42: SUPERVISOR SEBIN | J42: P/C ROYLAD BELISARIO | O42: SUPERVISOR SEBIN | P42: P/C ROYLAD BELISARIO | U42: SUPERVISOR SEBIN | V42: P/C ROYLAD BELISARIO | AA42: SUPERVISOR SEBIN | AB42: C/G XXXXX

Sheet CG RONNY GALDONAS
AI2: TOTALES
C3: CENTRO: UNIDAD EDUCATIVA NACIONAL DOCTOR GUILLERMO DELGADO PALACIOS | I3: CENTRO: LICEO JOSE AVALO | O3: CENTRO: U.E.N Gran Colombia 1 -EDIF. Colombia Edif.Colombia | U3: CENTRO: U.E.N. Gran Colombia 2- Edif. Perú | AA3: CENTRO: U.E.N Gran Colombia 3- Edif. Ecuador
B4: PRESENTACION | C4: TOTAL PERSONAS | D4: =D6+D7+D8+D9+D10+D11 -> 0 | H4: PRESENTACION | I4: TOTAL PERSONAS | J4: =J6+J7+J8+J9+J10+J11 -> 0 | N4: PRESENTACION | O4: TOTAL PERSONAS | P4: =+P6+P7+P8+P9+P10+P11 -> 180 | T4: PRESENTACION | U4: TOTAL PERSONAS | V4: =+V6+V7+V8+V9+V10+V11 -> 83 | Z4: PRESENTACION | AA4: TOTAL PERSONAS | AB4: 69 | AI4: TOTAL PERSONAS | AJ4: 332
C5: NRO. FAMILIAS | D5: 0 | I5: NRO. FAMILIAS | J5: 0 | O5: NRO. FAMILIAS | P5: 62 | U5: NRO. FAMILIAS | V5: 23 | AA5: NRO. FAMILIAS | AB5: 0 | AI5: NRO. FAMILIAS | AJ5: 85
C6: HOMBRES | D6: 0 | I6: HOMBRES | J6: 0 | O6: HOMBRES | P6: 57 | U6: HOMBRES | V6: 28 | AA6: HOMBRES | AB6: 0 | AI6: HOMBRES | AJ6: 85
C7: MUJERES | D7: 0 | I7: MUJERES | J7: 0 | O7: MUJERES | P7: 40 | U7: MUJERES | V7: 23 | AA7: MUJERES | AB7: 0 | AI7: MUJERES | AJ7: 63
C8: NIÑOS | D8: 0 | I8: NIÑOS | J8: 0 | O8: NIÑOS | P8: 27 | U8: NIÑOS | V8: 16 | AA8: NIÑOS | AB8: 0 | AI8: NIÑOS | AJ8: 43
C9: NIÑAS | D9: 0 | I9: NIÑAS | J9: 0 | O9: NIÑAS | P9: 40 | U9: NIÑAS | V9: 15 | AA9: NIÑAS | AB9: 0 | AI9: NIÑAS | AJ9: 55
C10: ADULTOS MAYORES | D10: 0 | I10: ADULTOS MAYORES | J10: 0 | O10: ADULTOS MAYORES | P10: 6 | U10: ADULTOS MAYORES | V10: 1 | AA10: ADULTOS MAYORES | AB10: 0 | AI10: ADULTOS MAYORES | AJ10: 7
C11: ADULTAS MAYORES | D11: 0 | E11: FOTO DEL CENTRO | I11: ADULTAS MAYORES | J11: 0 | K11: FOTO DEL CENTRO | O11: ADULTAS MAYORES | P11: 10 | Q11: FOTO DEL CENTRO | U11: ADULTAS MAYORES | V11: 0 | W11: FOTO DEL CENTRO | AA11: ADULTAS MAYORES | AB11: 0 | AC11: FOTO DEL CENTRO | AI11: ADULTAS MAYORES | AJ11: 10
C12: PER. CON DISCAPACIDAD | D12: 0 | I12: PER. CON DISCAPACIDAD | J12: 0 | O12: PER. CON DISCAPACIDAD | P12: 0 | U12: PER. CON DISCAPACIDAD | V12: 0 | AA12: PER. CON DISCAPACIDAD | AB12: 0 | AI12: PER. CON DISCAPACIDAD | AJ12: 0
C13: EMBARAZADAS | D13: 0 | I13: EMBARAZADAS | J13: 0 | O13: EMBARAZADAS | P13: 0 | U13: EMBARAZADAS | V13: 0 | AA13: EMBARAZADAS | AB13: 0 | AI13: EMBARAZADAS | AJ13: 0
C14: CASOS DE SALUD | D14: 0 | I14: CASOS DE SALUD | J14: 0 | O14: CASOS DE SALUD | P14: 0 | U14: CASOS DE SALUD | V14: 0 | AA14: CASOS DE SALUD | AB14: 0 | AI14: CASOS DE SALUD | AJ14: 0
C15: MASCOTAS | D15: 0 | I15: MASCOTAS | J15: 0 | O15: MASCOTAS | P15: 0 | U15: MASCOTAS | V15: 0 | AA15: MASCOTAS | AB15: 0 | AI15: MASCOTAS | AJ15: 0
B17: I | C17: ESTADO | D17: DTTO. CAPITAL | H17: I | I17: ESTADO | J17: DTTO. CAPITAL | N17: I | O17: ESTADO | P17: DTTO. CAPITAL | T17: I | U17: ESTADO | V17: DTTO. CAPITAL | Z17: I | AA17: ESTADO | AB17: DTTO. CAPITAL
